// File: frontend/components/__tests__/ErrorBoundary.test.js
import React from 'react';
import { render, screen, fireEvent } from '@testing-library/react';
import ErrorBoundary from '../ErrorBoundary';

const ThrowError = () => {
  throw new Error('Test error');
};

describe('ErrorBoundary', () => {
  beforeEach(() => {
    // Suppress console.error for expected error
    jest.spyOn(console, 'error').mockImplementation(() => {});
  });

  afterEach(() => {
    console.error.mockRestore();
  });

  it('renders children when there is no error', () => {
    render(
      <ErrorBoundary>
        <div>Test content</div>
      </ErrorBoundary>
    );

    expect(screen.getByText('Test content')).toBeInTheDocument();
  });

  it('renders error UI when there is an error', () => {
    render(
      <ErrorBoundary>
        <ThrowError />
      </ErrorBoundary>
    );

    expect(screen.getByText('Something went wrong')).toBeInTheDocument();
    expect(screen.getByText(/We apologize for the inconvenience/)).toBeInTheDocument();
  });

  it('logs error to console when there is an error', () => {
    render(
      <ErrorBoundary>
        <ThrowError />
      </ErrorBoundary>
    );

    expect(console.error).toHaveBeenCalled();
  });

  it('resets error state when try again button is clicked', () => {
    render(
      <ErrorBoundary>
        <ThrowError />
      </ErrorBoundary>
    );

    expect(screen.getByText('Something went wrong')).toBeInTheDocument();

    fireEvent.click(screen.getByText('Try again'));

    // The error boundary should still show the error UI because the error is still being thrown
    expect(screen.getByText('Something went wrong')).toBeInTheDocument();
  });
});